Workbook

Sheet STOK STB BJ
A1: PT SUPRACOR SEJAHTERA — DATA STOK BARANG JADI (STB BJ)
A2: Sumber: BOX_AGUSTUS.xlsx sheet "BOX" (Daily Stock Box) | Stok Awal = kolom SALDO AWAL (01 Agu 2026), Stok Akhir = kolom SALDO AKHIR
A3: TANGGAL CUT-OFF STOK AKHIR | C3: 46237
A4: BATAS "STOK KECIL" | C4: 150 | D4: PC | E4: 10 | F4: KG | G4: << sel kuning boleh diubah; UMUR & KATEGORI AGING otomatis menyesuaikan
A5: NO | B5: CUSTOMER | C5: ITEM | D5: UKURAN | E5: BERAT (KG/PC) | F5: NO. MC | G5: NO. OP | H5: TGL PRODUKSI TERAKHIR | I5: QTY ORDER | J5: STOK AWAL (PC) | K5: STOK AWAL (KG) | L5: STOK AKHIR (PC) | M5: STOK AKHIR (KG) | N5: UMUR (HARI) | O5: KATEGORI AGING | P5: KETERANGAN | Q5: INTERNAL | R5: SALES
A6: 1 | B6: AIDA ARTAN | C6: BOX SNACK BABY BOSS 20 G | D6: 460 x 344 x 295 | E6: 0.39265 | F6: A031-2600100-A1 | G6: 2607/00462 | H6: 46235 | I6: 10000 | J6: 0 | K6: 0 | L6: 9500 | M6: 3730.175 | N6: =IF(H6="","",$C$3-H6) -> 2 | O6: =IF(AND(L6<=$C$4,M6<=$E$4),"<=150pc & <=10kg",IF(N6="","TANPA TGL",IF(N6<=5,"<= 5 HARI",IF(N6<=7,"<= 7 HARI",IF(N6<=14,"<= 14 HARI","> 14 HARI"))))) -> <= 5 HARI | Q6: MIFTA | R6: NAC
A7: 2 | B7: AIR GANGGA DEWATA ALAMI, PT | C7: ECOQUA 220 ML NEW DESIGN | D7: 342 x 234 x 191 | E7: 0.21637 | F7: 0017414 | G7: 2607/01075 | H7: 46232 | I7: 80000 | J7: 1180 | K7: 255.3166 | L7: 1180 | M7: 255.3166 | N7: =IF(H7="","",$C$3-H7) -> 5 | O7: =IF(AND(L7<=$C$4,M7<=$E$4),"<=150pc & <=10kg",IF(N7="","TANPA TGL",IF(N7<=5,"<= 5 HARI",IF(N7<=7,"<= 7 HARI",IF(N7<=14,"<= 14 HARI","> 14 HARI"))))) -> <= 5 HARI | Q7: MINUK | R7: IFAN
A8: 3 | B8: AKASHA WIRA INTERNATIONAL PT TBK | C8: (56220501) WRAP AROUND CARTON BOX ADES 600 ML | D8: 400 X 237 X 268 | E8: 0.28119 | F8: 0015651F | G8: 2606/01282 | H8: 46233 | I8: 392000 | J8: 1010 | K8: 284.0019 | L8: 1010 | M8: 284.0019 | N8: =IF(H8="","",$C$3-H8) -> 4 | O8: =IF(AND(L8<=$C$4,M8<=$E$4),"<=150pc & <=10kg",IF(N8="","TANPA TGL",IF(N8<=5,"<= 5 HARI",IF(N8<=7,"<= 7 HARI",IF(N8<=14,"<= 14 HARI","> 14 HARI"))))) -> <= 5 HARI | Q8: WINDA | R8: SAMUEL
A9: 4 | B9: AKE ABADI, CV | C9: KARTON AKE 200 ML (48) MANADO | D9: 340 x 238 x 180 | E9: 0.22995 | F9: A022-2600100-A1 | G9: 2605/00660 | H9: 46221 | I9: 384000 | J9: 4260 | K9: 979.587 | L9: 4260 | M9: 979.587 | N9: =IF(H9="","",$C$3-H9) -> 16 | O9: =IF(AND(L9<=$C$4,M9<=$E$4),"<=150pc & <=10kg",IF(N9="","TANPA TGL",IF(N9<=5,"<= 5 HARI",IF(N9<=7,"<= 7 HARI",IF(N9<=14,"<= 14 HARI","> 14 HARI"))))) -> > 14 HARI | P9: SISA CONTAINER | Q9: MIFTA | R9: NAC
A10: 5 | B10: ALBEXON JAYA SUKSES MAKMUR, CV | C10: TOPLES JD 3/4 DIAMOND | D10: 369 x 369 x 152 | E10: 0.29467 | F10: BF0121 | G10: 2607/00940 | H10: 46231 | I10: 3000 | J10: 3100 | K10: 913.477 | L10: 3100 | M10: 913.477 | N10: =IF(H10="","",$C$3-H10) -> 6 | O10: =IF(AND(L10<=$C$4,M10<=$E$4),"<=150pc & <=10kg",IF(N10="","TANPA TGL",IF(N10<=5,"<= 5 HARI",IF(N10<=7,"<= 7 HARI",IF(N10<=14,"<= 14 HARI","> 14 HARI"))))) -> <= 7 HARI | Q10: MALA | R10: MIRZA
A11: 6 | B11: ALP PETRO INDUSTRY, PT | C11: (RMEA-309-PK0014) CARTON BOX KRAFT EURO 5L X 4 BOTOL | D11: 449 x 234 x 302 | E11: 0.77205 | F11: BE29312 | G11: 2607/01142 | H11: 46235 | I11: 3000 | J11: 1100 | K11: 849.255 | L11: 3140 | M11: 2424.237 | N11: =IF(H11="","",$C$3-H11) -> 2 | O11: =IF(AND(L11<=$C$4,M11<=$E$4),"<=150pc & <=10kg",IF(N11="","TANPA TGL",IF(N11<=5,"<= 5 HARI",IF(N11<=7,"<= 7 HARI",IF(N11<=14,"<= 14 HARI","> 14 HARI"))))) -> <= 5 HARI | P11: TUNGGU JADWAL | Q11: RISTA | R11: HERU
A12: 7 | B12: ANDRIANI | C12: AMDK LOE 220 ML | D12: 350 X 233 X 190 | E12: 0.19195 | F12: 0015477 | G12: 2605/01086 | H12: 46227 | I12: 80000 | J12: 3660 | K12: 702.537 | L12: 3660 | M12: 702.537 | N12: =IF(H12="","",$C$3-H12) -> 10 | O12: =IF(AND(L12<=$C$4,M12<=$E$4),"<=150pc & <=10kg",IF(N12="","TANPA TGL",IF(N12<=5,"<= 5 HARI",IF(N12<=7,"<= 7 HARI",IF(N12<=14,"<= 14 HARI","> 14 HARI"))))) -> <= 14 HARI | P12: SISA CONTAINER | Q12: MINUK | R12: IFAN
A13: 8 | B13: ANEKA RUPA TERA, PT | C13: DUS POLOS (UK. 330 X 320 X 190) | D13: 330 x 320 x 190 | E13: 0.30666 | F13: 0022867 | G13: 2607/00431 | H13: 46221 | I13: 2000 | J13: 200 | K13: 61.332 | L13: 200 | M13: 61.332 | N13: =IF(H13="","",$C$3-H13) -> 16 | O13: =IF(AND(L13<=$C$4,M13<=$E$4),"<=150pc & <=10kg",IF(N13="","TANPA TGL",IF(N13<=5,"<= 5 HARI",IF(N13<=7,"<= 7 HARI",IF(N13<=14,"<= 14 HARI","> 14 HARI"))))) -> > 14 HARI | P13: KURANG KIRIM | Q13: RISTA | R13: EDI
A14: 9 | B14: ANEKA RUPA TERA, PT | C14: DUS ART UK. 370 X 370 X 265 | D14: 370 X 370 X 265 | E14: 0.43022 | F14: 0022203 | G14: 2607/01099 | H14: 46235 | I14: 1500 | J14: 1420 | K14: 610.9124 | L14: 0 | M14: 0 | N14: =IF(H14="","",$C$3-H14) -> 2 | O14: =IF(AND(L14<=$C$4,M14<=$E$4),"<=150pc & <=10kg",IF(N14="","TANPA TGL",IF(N14<=5,"<= 5 HARI",IF(N14<=7,"<= 7 HARI",IF(N14<=14,"<= 14 HARI","> 14 HARI"))))) -> <=150pc & <=10kg | Q14: RISTA | R14: EDI
A15: 10 | B15: ANUGERAH MULIA BOX,CV | C15: FROZEN FISH POLOS K200 / M125 / K200 | D15: 495 x 310 x 95 | E15: 0.39702 | F15: BE27907X9 | G15: 2607/00826 | H15: 46227 | I15: 3200 | J15: 3700 | K15: 1468.974 | L15: 3700 | M15: 1468.974 | N15: =IF(H15="","",$C$3-H15) -> 10 | O15: =IF(AND(L15<=$C$4,M15<=$E$4),"<=150pc & <=10kg",IF(N15="","TANPA TGL",IF(N15<=5,"<= 5 HARI",IF(N15<=7,"<= 7 HARI",IF(N15<=14,"<= 14 HARI","> 14 HARI"))))) -> <= 14 HARI | P15: TUNGGU JADWAL | Q15: MALA | R15: SAMUEL
A16: 11 | B16: ANUGERAH MULIA BOX,CV | C16: POLOS 30 LBS | D16: 440 x 300 x 210 | E16: 0.71705 | F16: A004-2601500-A1 | G16: 2607/00941 | H16: 46232 | I16: 2200 | J16: 2200 | K16: 1577.51 | L16: 2200 | M16: 1577.51 | N16: =IF(H16="","",$C$3-H16) -> 5 | O16: =IF(AND(L16<=$C$4,M16<=$E$4),"<=150pc & <=10kg",IF(N16="","TANPA TGL",IF(N16<=5,"<= 5 HARI",IF(N16<=7,"<= 7 HARI",IF(N16<=14,"<= 14 HARI","> 14 HARI"))))) -> <= 5 HARI | Q16: MALA | R16: SAMUEL
A17: 12 | B17: ANUGERAH MULIA BOX,CV | C17: FROZEN NFE K125 / M125 / K110 | D17: 495 x 310 x 95 | E17: 0.28209 | F17: A004-2601700-DC | G17: 2607/01000 | H17: 46235 | I17: 14500 | J17: 11200 | K17: 3159.408 | L17: 14500 | M17: 4090.305 | N17: =IF(H17="","",$C$3-H17) -> 2 | O17: =IF(AND(L17<=$C$4,M17<=$E$4),"<=150pc & <=10kg",IF(N17="","TANPA TGL",IF(N17<=5,"<= 5 HARI",IF(N17<=7,"<= 7 HARI",IF(N17<=14,"<= 14 HARI","> 14 HARI"))))) -> <= 5 HARI | Q17: MALA | R17: SAMUEL
A18: 13 | B18: ANUGRAH MAJU KEMASINDO, PT | C18: BOX PECI NASIONAL | D18: 300 x 300 x 300 | E18: 0.31511 | F18: A025-2600600-A1 | G18: 2607/00853 | H18: 46233 | I18: 3500 | J18: 3500 | K18: 1102.885 | L18: 3500 | M18: 1102.885 | N18: =IF(H18="","",$C$3-H18) -> 4 | O18: =IF(AND(L18<=$C$4,M18<=$E$4),"<=150pc & <=10kg",IF(N18="","TANPA TGL",IF(N18<=5,"<= 5 HARI",IF(N18<=7,"<= 7 HARI",IF(N18<=14,"<= 14 HARI","> 14 HARI"))))) -> <= 5 HARI | Q18: AMEL | R18: RW
A19: 14 | B19: ARISU INDONESIA, PT | C19: HAZEL 50 REV, BOX | D19: 560 X 383 X 135 | E19: 0.48833 | F19: 0016708 | G19: 2606/00231 | H19: 46194 | I19: 3482 | J19: 390 | K19: 190.4487 | L19: 390 | M19: 190.4487 | N19: =IF(H19="","",$C$3-H19) -> 43 | O19: =IF(AND(L19<=$C$4,M19<=$E$4),"<=150pc & <=10kg",IF(N19="","TANPA TGL",IF(N19<=5,"<= 5 HARI",IF(N19<=7,"<= 7 HARI",IF(N19<=14,"<= 14 HARI","> 14 HARI"))))) -> > 14 HARI | P19: TUNGGU JADWAL | Q19: NUR | R19: WAWAN
A20: 15 | B20: ARISU INDONESIA, PT | C20: ULI D01 UK1, BOX | D20: 545 X 430 X 205 | E20: 0.59983 | F20: 0016677 | G20: 2607/00247 | H20: 46231 | I20: 15417 | J20: 1426 | K20: 855.35758 | L20: 1426 | M20: 855.35758 | N20: =IF(H20="","",$C$3-H20) -> 6 | O20: =IF(AND(L20<=$C$4,M20<=$E$4),"<=150pc & <=10kg",IF(N20="","TANPA TGL",IF(N20<=5,"<= 5 HARI",IF(N20<=7,"<= 7 HARI",IF(N20<=14,"<= 14 HARI","> 14 HARI"))))) -> <= 7 HARI | P20: TUNGGU JADWAL | Q20: NUR | R20: WAWAN
A21: 16 | B21: ARISU INDONESIA, PT | C21: ULI D01 UK1, COVER | D21: 567 X 440 X 50 | E21: 0.19873 | F21: 0016678 | G21: 2607/00248 | H21: 46231 | I21: 43353 | J21: 435 | K21: 86.44755 | L21: 435 | M21: 86.44755 | N21: =IF(H21="","",$C$3-H21) -> 6 | O21: =IF(AND(L21<=$C$4,M21<=$E$4),"<=150pc & <=10kg",IF(N21="","TANPA TGL",IF(N21<=5,"<= 5 HARI",IF(N21<=7,"<= 7 HARI",IF(N21<=14,"<= 14 HARI","> 14 HARI"))))) -> <= 7 HARI | P21: TUNGGU JADWAL | Q21: NUR | R21: WAWAN
A22: 17 | B22: AROMA DEWI, CV | C22: TEPUNG CRISPY | D22: 402 x 337 x 225 | E22: 0.40519 | F22: 0025287 | G22: 2606/01256 | H22: 46223 | I22: 10000 | J22: 5140 | K22: 2082.6766 | L22: 5140 | M22: 2082.6766 | N22: =IF(H22="","",$C$3-H22) -> 14 | O22: =IF(AND(L22<=$C$4,M22<=$E$4),"<=150pc & <=10kg",IF(N22="","TANPA TGL",IF(N22<=5,"<= 5 HARI",IF(N22<=7,"<= 7 HARI",IF(N22<=14,"<= 14 HARI","> 14 HARI"))))) -> <= 14 HARI | Q22: RISTA | R22: JONI
A23: 18 | B23: ASERA TIRTA POSIDONIA , PT | C23: BOX AMDK ASERA 48 X 220 ML | D23: 352 x 233 x 190 | E23: 0.23504 | F23: BF0128 | G23: 2607/00779 | H23: 46225 | I23: 45000 | J23: 2310 | K23: 542.9424 | L23: 2310 | M23: 542.9424 | N23: =IF(H23="","",$C$3-H23) -> 12 | O23: =IF(AND(L23<=$C$4,M23<=$E$4),"<=150pc & <=10kg",IF(N23="","TANPA TGL",IF(N23<=5,"<= 5 HARI",IF(N23<=7,"<= 7 HARI",IF(N23<=14,"<= 14 HARI","> 14 HARI"))))) -> <= 14 HARI | P23: SISA CONTAINER | Q23: WINDA | R23: SAMUEL
A24: 19 | B24: ASIA PACIFIC FIBERS, PT | C24: BOX BOTTOM JUMBO DTY 1000 "CARL WEISKE" | D24: 1,130 x 1,130 x 1,000 | E24: 9.10231 | F24: 0025359 | G24: 2607/00514 | H24: 46235 | I24: 2000 | J24: 0 | K24: 0 | L24: 350 | M24: 3185.8085 | N24: =IF(H24="","",$C$3-H24) -> 2 | O24: =IF(AND(L24<=$C$4,M24<=$E$4),"<=150pc & <=10kg",IF(N24="","TANPA TGL",IF(N24<=5,"<= 5 HARI",IF(N24<=7,"<= 7 HARI",IF(N24<=14,"<= 14 HARI","> 14 HARI"))))) -> <= 5 HARI | Q24: MAYUN | R24: BINTARA
A25: 20 | B25: ASIA PACIFIC FIBERS, PT | C25: LAYER JUMBO DTY 1 LAPIS DOUBLE WALL CW | D25: 1,130 x 1,130 | E25: 1.59357 | F25: BF0321 | G25: 2607/00517 | H25: 46235 | I25: 10000 | J25: 0 | K25: 0 | L25: 1000 | M25: 1593.57 | N25: =IF(H25="","",$C$3-H25) -> 2 | O25: =IF(AND(L25<=$C$4,M25<=$E$4),"<=150pc & <=10kg",IF(N25="","TANPA TGL",IF(N25<=5,"<= 5 HARI",IF(N25<=7,"<= 7 HARI",IF(N25<=14,"<= 14 HARI","> 14 HARI"))))) -> <= 5 HARI | P25: KURANG KIRIM | Q25: MAYUN | R25: BINTARA
A26: 21 | B26: AVIA AVIAN TBK, PT | C26: DS AVITEX TEMBOK 5 KG AW-07 | D26: 375 x 375 x 194 | E26: 0.66787 | F26: BF0062 | G26: 2606/01084 | H26: 46203 | I26: 2500 | J26: 310 | K26: 207.0397 | L26: 310 | M26: 207.0397 | N26: =IF(H26="","",$C$3-H26) -> 34 | O26: =IF(AND(L26<=$C$4,M26<=$E$4),"<=150pc & <=10kg",IF(N26="","TANPA TGL",IF(N26<=5,"<= 5 HARI",IF(N26<=7,"<= 7 HARI",IF(N26<=14,"<= 14 HARI","> 14 HARI"))))) -> > 14 HARI | P26: LEBIH PRODUKSI | Q26: WINDA | R26: SAMUEL
A27: 22 | B27: BADRI | C27: AMDK ALAS 220 ML | D27: 335 x 230 x 193 | E27: 0.18542 | F27: BE28725 | G27: 2606/00799 | H27: 46199 | I27: 12000 | J27: 2000 | K27: 370.84 | L27: 2000 | M27: 370.84 | N27: =IF(H27="","",$C$3-H27) -> 38 | O27: =IF(AND(L27<=$C$4,M27<=$E$4),"<=150pc & <=10kg",IF(N27="","TANPA TGL",IF(N27<=5,"<= 5 HARI",IF(N27<=7,"<= 7 HARI",IF(N27<=14,"<= 14 HARI","> 14 HARI"))))) -> > 14 HARI | P27: TUNGGU JADWAL | Q27: MAYUN | R27: BINTARA
A28: 23 | B28: BAMBANG HERMANTO | C28: BODY BOX SSF GOLD | D28: 647 X 490 X 210 | E28: 0.51331 | F28: 0022275F | G28: 2606/00774 | H28: 46212 | I28: 1000 | J28: 150 | K28: 76.9965 | L28: 150 | M28: 76.9965 | N28: =IF(H28="","",$C$3-H28) -> 25 | O28: =IF(AND(L28<=$C$4,M28<=$E$4),"<=150pc & <=10kg",IF(N28="","TANPA TGL",IF(N28<=5,"<= 5 HARI",IF(N28<=7,"<= 7 HARI",IF(N28<=14,"<= 14 HARI","> 14 HARI"))))) -> > 14 HARI | P28: TIDAK SET | Q28: MIFTA | R28: NAC
A29: 24 | B29: BEHAESTEX, PT | C29: DBL SR AS SUPREM 925 2025 | D29: 1,300 x 455 x 260 | E29: 2.05892 | F29: BF0244 | G29: 2606/00081 | H29: 46212 | I29: 4100 | J29: 125 | K29: 257.365 | L29: 125 | M29: 257.365 | N29: =IF(H29="","",$C$3-H29) -> 25 | O29: =IF(AND(L29<=$C$4,M29<=$E$4),"<=150pc & <=10kg",IF(N29="","TANPA TGL",IF(N29<=5,"<= 5 HARI",IF(N29<=7,"<= 7 HARI",IF(N29<=14,"<= 14 HARI","> 14 HARI"))))) -> > 14 HARI | P29: BELUM KETEMU | Q29: RISTA | R29: HERU
A30: 25 | B30: BERKAH SUMBER ABADI, CV | C30: BOX AMDK BST 220 ML NEW 2 | D30: 338 X 236 X 194 | E30: 0.21886 | F30: 0025855 | G30: 2602/01006 | H30: 46221 | I30: 80000 | J30: 880 | K30: 192.5968 | L30: 880 | M30: 192.5968 | N30: =IF(H30="","",$C$3-H30) -> 16 | O30: =IF(AND(L30<=$C$4,M30<=$E$4),"<=150pc & <=10kg",IF(N30="","TANPA TGL",IF(N30<=5,"<= 5 HARI",IF(N30<=7,"<= 7 HARI",IF(N30<=14,"<= 14 HARI","> 14 HARI"))))) -> > 14 HARI | P30: SISA CONTAINER | Q30: MAYUN | R30: BINTARA
A31: 26 | B31: BERKAT SEJAHTERA ERGA JAYA, CV | C31: ERIKO KODE V | D31: 624 X 564 X 786 | E31: 2.61148 | F31: 0023320 | G31: 2606/01178 | H31: 46213 | I31: 300 | J31: 75 | K31: 195.861 | L31: 75 | M31: 195.861 | N31: =IF(H31="","",$C$3-H31) -> 24 | O31: =IF(AND(L31<=$C$4,M31<=$E$4),"<=150pc & <=10kg",IF(N31="","TANPA TGL",IF(N31<=5,"<= 5 HARI",IF(N31<=7,"<= 7 HARI",IF(N31<=14,"<= 14 HARI","> 14 HARI"))))) -> > 14 HARI | Q31: NUR | R31: WAWAN
A32: 27 | B32: BLUE OCEAN FOODS INDONESIA , PT | C32: KARTON BRAND RADIANCE 155 G SARDINE IN TOMATO SAUCE (BROWN CRAFT) | D32: 336 x 225 x 91 | E32: 0.18057 | F32: BE28533 | G32: 2606/01045 | H32: 46203 | I32: 12300 | J32: 123 | K32: 22.21011 | L32: 123 | M32: 22.21011 | N32: =IF(H32="","",$C$3-H32) -> 34 | O32: =IF(AND(L32<=$C$4,M32<=$E$4),"<=150pc & <=10kg",IF(N32="","TANPA TGL",IF(N32<=5,"<= 5 HARI",IF(N32<=7,"<= 7 HARI",IF(N32<=14,"<= 14 HARI","> 14 HARI"))))) -> > 14 HARI | P32: LEBIH PRODUKSI | Q32: MIFTA | R32: NAC
A33: 28 | B33: BLUE OCEAN FOODS INDONESIA , PT | C33: KARTON NOSH SARDINES IN SOYBEAN OIL WITH CHILLI | D33: 313 x 213 x 128 | E33: 0.19048 | F33: BE29432 | G33: 2607/00833 | H33: 46225 | I33: 3600 | J33: 100 | K33: 19.048 | L33: 100 | M33: 19.048 | N33: =IF(H33="","",$C$3-H33) -> 12 | O33: =IF(AND(L33<=$C$4,M33<=$E$4),"<=150pc & <=10kg",IF(N33="","TANPA TGL",IF(N33<=5,"<= 5 HARI",IF(N33<=7,"<= 7 HARI",IF(N33<=14,"<= 14 HARI","> 14 HARI"))))) -> <= 14 HARI | P33: TUNGGU JADWAL | Q33: MIFTA | R33: NAC
A34: 29 | B34: BONDVAST INDO SUKSES, PT | C34: P-NK-12001200-ID SERAT LAYER (GARIS TEKAN / DIECUT) | D34: 1,200 x 1,200 | E34: 0.8208 | F34: 0026591F | G34: 2607/00072 | H34: 46235 | I34: 4600 | J34: 1720 | K34: 1411.776 | L34: 1978 | M34: 1623.5424 | N34: =IF(H34="","",$C$3-H34) -> 2 | O34: =IF(AND(L34<=$C$4,M34<=$E$4),"<=150pc & <=10kg",IF(N34="","TANPA TGL",IF(N34<=5,"<= 5 HARI",IF(N34<=7,"<= 7 HARI",IF(N34<=14,"<= 14 HARI","> 14 HARI"))))) -> <= 5 HARI | P34: LEBIH PRODUKSI | Q34: MALA | R34: MIRZA
A35: 30 | B35: BONDVAST INDO SUKSES, PT | C35: P-NY-16201011-ID SERAT LAYER (GARIS TEKAN) | D35: 1,011 x 1,620 | E35: 0.93356 | F35: B009-2600500-DC | G35: 2607/00924 | H35: 46233 | I35: 4475 | J35: 520 | K35: 485.4512 | L35: 520 | M35: 485.4512 | N35: =IF(H35="","",$C$3-H35) -> 4 | O35: =IF(AND(L35<=$C$4,M35<=$E$4),"<=150pc & <=10kg",IF(N35="","TANPA TGL",IF(N35<=5,"<= 5 HARI",IF(N35<=7,"<= 7 HARI",IF(N35<=14,"<= 14 HARI","> 14 HARI"))))) -> <= 5 HARI | Q35: MALA | R35: MIRZA
A36: 31 | B36: BUANA MAHAYASA SAKTI | C36: BOX 106 GR BOTTOM | D36: 655 x 375 x 106 | E36: 0.34193 | F36: B013-2600100-DB | G36: 2607/00093 | H36: 46215 | I36: 2500 | J36: 300 | K36: 102.579 | L36: 0 | M36: 0 | N36: =IF(H36="","",$C$3-H36) -> 22 | O36: =IF(AND(L36<=$C$4,M36<=$E$4),"<=150pc & <=10kg",IF(N36="","TANPA TGL",IF(N36<=5,"<= 5 HARI",IF(N36<=7,"<= 7 HARI",IF(N36<=14,"<= 14 HARI","> 14 HARI"))))) -> <=150pc & <=10kg | P36: TUNGGU JADWAL | Q36: MAYUN | R36: BINTARA
A37: 32 | B37: BUANA MAHAYASA SAKTI | C37: BOX 106 GR TOP | D37: 675 x 385 x 50 | E37: 0.1693 | F37: B013-2600100-DT | G37: 2607/00093 | H37: 46215 | I37: 2500 | J37: 300 | K37: 50.79 | L37: 0 | M37: 0 | N37: =IF(H37="","",$C$3-H37) -> 22 | O37: =IF(AND(L37<=$C$4,M37<=$E$4),"<=150pc & <=10kg",IF(N37="","TANPA TGL",IF(N37<=5,"<= 5 HARI",IF(N37<=7,"<= 7 HARI",IF(N37<=14,"<= 14 HARI","> 14 HARI"))))) -> <=150pc & <=10kg | P37: TUNGGU JADWAL | Q37: MAYUN | R37: BINTARA
A38: 33 | B38: BUANA MAHAYASA SAKTI | C38: BOX 86 GR BOTTOM | D38: 655 x 375 x 86 | E38: 0.29586 | F38: B013-2600200-DB | G38: 2607/00094 | H38: 46223 | I38: 2500 | J38: 1300 | K38: 384.618 | L38: 0 | M38: 0 | N38: =IF(H38="","",$C$3-H38) -> 14 | O38: =IF(AND(L38<=$C$4,M38<=$E$4),"<=150pc & <=10kg",IF(N38="","TANPA TGL",IF(N38<=5,"<= 5 HARI",IF(N38<=7,"<= 7 HARI",IF(N38<=14,"<= 14 HARI","> 14 HARI"))))) -> <=150pc & <=10kg | P38: TUNGGU JADWAL | Q38: MAYUN | R38: BINTARA
A39: 34 | B39: BUANA MAHAYASA SAKTI | C39: BOX 86 GR TOP | D39: 675 x 385 x 46 | E39: 0.1646 | F39: B013-2600200-DT | G39: 2607/00094 | H39: 46222 | I39: 2500 | J39: 1300 | K39: 213.98 | L39: 0 | M39: 0 | N39: =IF(H39="","",$C$3-H39) -> 15 | O39: =IF(AND(L39<=$C$4,M39<=$E$4),"<=150pc & <=10kg",IF(N39="","TANPA TGL",IF(N39<=5,"<= 5 HARI",IF(N39<=7,"<= 7 HARI",IF(N39<=14,"<= 14 HARI","> 14 HARI"))))) -> <=150pc & <=10kg | P39: TUNGGU JADWAL | Q39: MAYUN | R39: BINTARA
A40: 35 | B40: BUANA MAHAYASA SAKTI CV | C40: BOTT 134 (653 X 365 X 134) TANPA LOGO BMS | D40: 655 X 366 X 134 | E40: 0.34495 | F40: 0026596F | G40: 2601/00538 | H40: 46155 | I40: 3000 | J40: 195 | K40: 67.26525 | L40: 195 | M40: 67.26525 | N40: =IF(H40="","",$C$3-H40) -> 82 | O40: =IF(AND(L40<=$C$4,M40<=$E$4),"<=150pc & <=10kg",IF(N40="","TANPA TGL",IF(N40<=5,"<= 5 HARI",IF(N40<=7,"<= 7 HARI",IF(N40<=14,"<= 14 HARI","> 14 HARI"))))) -> > 14 HARI | P40: TUNGGU JADWAL | Q40: MAYUN | R40: BINTARA
...

Sheet REKAP PER OP
A1: REKAP STOK STB BJ PER NO. OP (siap import ke database)
A2: Satu baris = satu NO. OP (cNoSc). Baris ganda pada sheet detail sudah dijumlahkan.
A4: NO | B4: NO. OP (cNoSc) | C4: CUSTOMER | D4: ITEM | E4: TGL PRODUKSI TERAKHIR | F4: STOK AWAL (PC) | G4: STOK AWAL (KG) | H4: STOK AKHIR (PC) | I4: STOK AKHIR (KG) | J4: KETERANGAN
A5: 1 | B5: 2505/01199 | C5: SINAR KEMASAN TERANG, PT | D5: OB AIR ACCU 1 LT | E5: 46225 | F5: 2100 | G5: 654.759 | H5: 2100 | I5: 654.759
A6: 2 | B6: 2511/00798 | C6: GUNUNG AGUNG SENTOSA, PT | D6: IB CERMIN OVAL S 014 | E6: 46188 | F6: 400 | G6: 33.816 | H6: 400 | I6: 33.816
A7: 3 | B7: 2512/00047 | C7: KEMBANG JAYA CV | D7: FAZZA ISI 40 X 220 ML NEW | E7: 46074 | F7: 1600 | G7: 308.528 | H7: 1600 | I7: 308.528 | J7: AMBIL SENDIRI
A8: 4 | B8: 2601/00538 | C8: BUANA MAHAYASA SAKTI CV | D8: BOTT 134 (653 X 365 X 134) TANPA LOGO BMS | E8: 46156 | F8: 454 | G8: 113.82827 | H8: 454 | I8: 113.82827 | J8: TUNGGU JADWAL
A9: 5 | B9: 2602/00117 | C9: MUHAMMAD SYAHRIR | D9: BBC | E9: 46063 | F9: 2120 | G9: 758.1544 | H9: 2120 | I9: 758.1544 | J9: SISA CONTAINER
A10: 6 | B10: 2602/00226 | C10: HBFULLER ADHESIVES INDONESIA, PT | D10: P123 (355 X 265 X 380 MM) | E10: 46223 | F10: 280 | G10: 250.4488 | H10: 280 | I10: 250.4488 | J10: TUNGGU JADWAL
A11: 7 | B11: 2602/00228 | C11: HBFULLER ADHESIVES INDONESIA, PT | D11: P124 (483 X 288 X 246 MM) | E11: 46176 | F11: 2800 | G11: 2577.736 | H11: 2800 | I11: 2577.736 | J11: TUNGGU JADWAL
A12: 8 | B12: 2602/00978 | C12: CENDRAWASIH DWIMEGA KENCANA | D12: AMDK CENDRAQUA 220 ML | E12: 46080 | F12: 1980 | G12: 428.076 | H12: 1980 | I12: 428.076 | J12: SISA CONTAINER
A13: 9 | B13: 2602/01006 | C13: BERKAH SUMBER ABADI, CV | D13: BOX AMDK BST 220 ML NEW 2 | E13: 46221 | F13: 880 | G13: 192.5968 | H13: 880 | I13: 192.5968 | J13: SISA CONTAINER
A14: 10 | B14: 2603/00552 | C14: NIPSEA PAINT AND CHEMICALS. PT | D14: PN114 VINILEX CCM 5KG O/T SW DC | E14: 46138 | F14: 1040 | G14: 243.1832 | H14: 1040 | I14: 243.1832
A15: 11 | B15: 2603/00557 | C15: NIPSEA PAINT AND CHEMICALS. PT | D15: PN106 NIPPON HI EPOXY FILLER BASE 12X0,8L SW | E15: 46209 | F15: 2300 | G15: 542.432 | H15: 2300 | I15: 542.432
A16: 12 | B16: 2603/00609 | C16: MASPION, PT | D16: DOOS LUAR MSC 1860 | E16: 46147 | F16: 150 | G16: 195.429 | H16: 150 | I16: 195.429 | J16: TUNGGU JADWAL
A17: 13 | B17: 2603/00918 | C17: CHAROEN POKPHAND INDONESIA, PT | D17: MC FIESTA RTG NEW ISI 6 BOX | E17: 46163 | F17: 120 | G17: 46.8708 | H17: 120 | I17: 46.8708 | J17: LEBIH PRODUKSI
A18: 14 | B18: 2604/00148 | C18: KEMBANG JAYA CV | D18: FAZZA ISI 45 X 120 ML NEW | E18: 46165 | F18: 1500 | G18: 234.795 | H18: 1500 | I18: 234.795 | J18: AMBIL SENDIRI
A19: 15 | B19: 2604/00311 | C19: BUANA MAHAYASA SAKTI CV | D19: TOP 102 | E19: 46134 | F19: 504 | G19: 83.19024 | H19: 504 | I19: 83.19024 | J19: TUNGGU JADWAL
A20: 16 | B20: 2604/00577 | C20: FADLAN | D20: AMDK SEGAR - 48 X 220 ML NEW | E20: 46131 | F20: 4460 | G20: 950.426 | H20: 4460 | I20: 950.426 | J20: SISA CONTAINER
A21: 17 | B21: 2604/00635 | C21: VPOL TIRTA SEJAHTERA, PT | D21: VPOL 220 ML | E21: 46207 | F21: 2620 | G21: 648.8168 | H21: 2620 | I21: 648.8168 | J21: SISA CONTAINER
A22: 18 | B22: 2604/00650 | C22: GUNUNG STARLINDO UTAMA, PT | D22: KARTON PH 4 MINI | E22: 46181 | F22: 150 | G22: 163.0185 | H22: 150 | I22: 163.0185
A23: 19 | B23: 2604/00871 | C23: KARUNIA TIRTA KAJUARA, PT | D23: KARTON WT 200 ML | E23: 46203 | F23: 4020 | G23: 791.8596 | H23: 4020 | I23: 791.8596 | J23: SISA CONTAINER
A24: 20 | B24: 2604/01094 | C24: ENDRIAN RUSLIM, | D24: FROZEN NFE | E24: 46141 | F24: 460 | G24: 134.5684 | H24: 460 | I24: 134.5684 | J24: SISA CONTAINER
A25: 21 | B25: 2604/01220 | C25: SIANTAR TOP TBK, PT | D25: DUS SPIX MIE GORENG SAMBAL BALADO CBP 500 ISI 100 PCS KTN/SMG-BDR500/L/100/01 | E25: 46233 | F25: 760 | G25: 127.1708 | H25: 760 | I25: 127.1708 | J25: KURANG KIRIM
A26: 22 | B26: 2604/01260 | C26: KERAMIK DIAMOND INDUSTRIES | D26: 40 X 40 ARTKERAMIK KW 1 | E26: 46223 | F26: 650 | G26: 74.9645 | H26: 650 | I26: 74.9645
A27: 23 | B27: 2605/00060 | C27: FRUIT ING INDONESIA, PT | D27: BOX BOTTOM | E27: 46169 | F27: 197 | G27: 117.63855 | H27: 197 | I27: 117.63855 | J27: TIDAK SET
A28: 24 | B28: 2605/00209 | C28: MULTI NABATI SULAWESI, PT | D28: SOVIA BIB 18 L | E28: 46226 | F28: 980 | G28: 648.809 | H28: 980 | I28: 648.809 | J28: SISA CONTAINER
A29: 25 | B29: 2605/00255 | C29: MEGASURYA MAS, PT | D29: BOX REFILL MINYAK 1 LTR MSM 2016 - SUNCO POUCH 1 L 04-05-23 | E29: 46231 | F29: 1870 | G29: 803.8569 | H29: 1870 | I29: 803.8569
A30: 26 | B30: 2605/00283 | C30: GRANDVILLE FOOD INDONESIA | D30: KARDUS KECIL | E30: 46194 | F30: 240 | G30: 13.068 | H30: 240 | I30: 13.068 | J30: BELUM KETEMU
A31: 27 | B31: 2605/00291 | C31: HBFULLER ADHESIVES INDONESIA, PT | D31: P162 (355 X 265 X 380 MM) KR BCF WITH-ACS-TAPE | E31: 46204 | F31: 840 | G31: 677.9052 | H31: 840 | I31: 677.9052 | J31: TUNGGU JADWAL
A32: 28 | B32: 2605/00317 | C32: PERSEROAN TERBATAS - BADAN HALIMJAYA SAKTI | D32: BOX ANDO HAWAI (AB) | E32: 46160 | F32: 630 | G32: 314.0298 | H32: 630 | I32: 314.0298 | J32: TUNGGU JADWAL
A33: 29 | B33: 2605/00354 | C33: ROMAN CERAMIC INTERNATIONAL, PT | D33: (GCAR5SD076) CART 5S THICK TILE RM TS GR 30 X 30 KW I | E33: 46200 | F33: 550 | G33: 141.3115 | H33: 550 | I33: 141.3115
A34: 30 | B34: 2605/00355 | C34: ROMAN CERAMIC INTERNATIONAL, PT | D34: (GCAR4SD094) CART 4S RM GRANIT 60 X 30 GRADE A | E34: 46235 | F34: 0 | G34: 0 | H34: 12200 | I34: 1025.41
A35: 31 | B35: 2605/00361 | C35: ROMAN CERAMIC INTERNATIONAL, PT | D35: (GCAR5SD141) CART 5S RM TS GR 120 X 60 GRADE A | E35: 46215 | F35: 375 | G35: 221.23125 | H35: 375 | I35: 221.23125
A36: 32 | B36: 2605/00370 | C36: NOFITA WAMIR | D36: LIPOKU 220 ML | E36: 46218 | F36: 8940 | G36: 1768.6896 | H36: 8940 | I36: 1768.6896 | J36: TUNGGU JADWAL
A37: 33 | B37: 2605/00528 | C37: PERSEROAN TERBATAS - BADAN HALIMJAYA SAKTI | D37: BOX GEMOY PRIA | E37: 46211 | F37: 600 | G37: 623.358 | H37: 600 | I37: 623.358 | J37: TUNGGU JADWAL
A38: 34 | B38: 2605/00530 | C38: PERSEROAN TERBATAS - BADAN HALIMJAYA SAKTI | D38: BOX ANDO HAWAI | E38: 46219 | F38: 880 | G38: 469.2864 | H38: 880 | I38: 469.2864 | J38: TUNGGU JADWAL
A39: 35 | B39: 2605/00592 | C39: LOTUS INDAH TEXTILE INDUSTRIES, PT | D39: LAYER LOTUS 545 X 280 | E39: 46178 | F39: 1500 | G39: 99 | H39: 1500 | I39: 99 | J39: TUNGGU JADWAL
A40: 36 | B40: 2605/00597 | C40: LOTUS INDAH TEXTILE INDUSTRIES, PT | D40: BOX 555 X 365 X 345 NON LOGO | E40: 46179 | F40: 180 | G40: 152.5122 | H40: 180 | I40: 152.5122 | J40: TUNGGU JADWAL
A41: 37 | B41: 2605/00600 | C41: LOTUS INDAH TEXTILE INDUSTRIES, PT | D41: LAYER LOTUS 550 X 360 | E41: 46161 | F41: 2000 | G41: 172.82 | H41: 2000 | I41: 172.82 | J41: TUNGGU JADWAL
...

Sheet REKAP AGING
A1: REKAP AGING & KETERANGAN STOK (mengikuti format sheet "Aging Stock")
A3: PER KATEGORI UMUR (basis STOK AKHIR)
A4: KATEGORI | B4: QTY (PCS) | C4: QTY (KG) | D4: JML ITEM
A5: <= 5 HARI | B5: =SUMPRODUCT(('STOK STB BJ'!$O$6:$O$302=A5)*'STOK STB BJ'!$L$6:$L$302) -> 532909 | C5: =SUMPRODUCT(('STOK STB BJ'!$O$6:$O$302=A5)*'STOK STB BJ'!$M$6:$M$302) -> 161629.18 | D5: =SUMPRODUCT(--('STOK STB BJ'!$O$6:$O$302=A5)) -> 88
A6: <= 7 HARI | B6: =SUMPRODUCT(('STOK STB BJ'!$O$6:$O$302=A6)*'STOK STB BJ'!$L$6:$L$302) -> 36949 | C6: =SUMPRODUCT(('STOK STB BJ'!$O$6:$O$302=A6)*'STOK STB BJ'!$M$6:$M$302) -> 14536.381 | D6: =SUMPRODUCT(--('STOK STB BJ'!$O$6:$O$302=A6)) -> 22
A7: <= 14 HARI | B7: =SUMPRODUCT(('STOK STB BJ'!$O$6:$O$302=A7)*'STOK STB BJ'!$L$6:$L$302) -> 54323 | C7: =SUMPRODUCT(('STOK STB BJ'!$O$6:$O$302=A7)*'STOK STB BJ'!$M$6:$M$302) -> 19420.616 | D7: =SUMPRODUCT(--('STOK STB BJ'!$O$6:$O$302=A7)) -> 39
A8: > 14 HARI | B8: =SUMPRODUCT(('STOK STB BJ'!$O$6:$O$302=A8)*'STOK STB BJ'!$L$6:$L$302) -> 152305 | C8: =SUMPRODUCT(('STOK STB BJ'!$O$6:$O$302=A8)*'STOK STB BJ'!$M$6:$M$302) -> 43070.652 | D8: =SUMPRODUCT(--('STOK STB BJ'!$O$6:$O$302=A8)) -> 114
A9: <=150pc & <=10kg | B9: =SUMPRODUCT(('STOK STB BJ'!$O$6:$O$302=A9)*'STOK STB BJ'!$L$6:$L$302) -> 14 | C9: =SUMPRODUCT(('STOK STB BJ'!$O$6:$O$302=A9)*'STOK STB BJ'!$M$6:$M$302) -> 1.90148 | D9: =SUMPRODUCT(--('STOK STB BJ'!$O$6:$O$302=A9)) -> 34
A10: TANPA TGL | B10: =SUMPRODUCT(('STOK STB BJ'!$O$6:$O$302=A10)*'STOK STB BJ'!$L$6:$L$302) -> 0 | C10: =SUMPRODUCT(('STOK STB BJ'!$O$6:$O$302=A10)*'STOK STB BJ'!$M$6:$M$302) -> 0 | D10: =SUMPRODUCT(--('STOK STB BJ'!$O$6:$O$302=A10)) -> 0
A11: TOTAL | B11: =SUM(B5:B10) -> 776500 | C11: =SUM(C5:C10) -> 238658.73 | D11: =SUM(D5:D10) -> 297
A13: PER KETERANGAN (basis STOK AKHIR)
A14: KETERANGAN | B14: QTY (PCS) | C14: QTY (KG) | D14: JML ITEM
A15: AMBIL SENDIRI | B15: =SUMIF('STOK STB BJ'!$P$6:$P$302,A15,'STOK STB BJ'!$L$6:$L$302) -> 6260 | C15: =SUMIF('STOK STB BJ'!$P$6:$P$302,A15,'STOK STB BJ'!$M$6:$M$302) -> 1307.7914 | D15: =COUNTIF('STOK STB BJ'!$P$6:$P$302,A15) -> 4
A16: SISA CONTAINER | B16: =SUMIF('STOK STB BJ'!$P$6:$P$302,A16,'STOK STB BJ'!$L$6:$L$302) -> 119646 | C16: =SUMIF('STOK STB BJ'!$P$6:$P$302,A16,'STOK STB BJ'!$M$6:$M$302) -> 27921.999 | D16: =COUNTIF('STOK STB BJ'!$P$6:$P$302,A16) -> 24
A17: TUNGGU CONTAINER | B17: =SUMIF('STOK STB BJ'!$P$6:$P$302,A17,'STOK STB BJ'!$L$6:$L$302) -> 0 | C17: =SUMIF('STOK STB BJ'!$P$6:$P$302,A17,'STOK STB BJ'!$M$6:$M$302) -> 0 | D17: =COUNTIF('STOK STB BJ'!$P$6:$P$302,A17) -> 0
A18: LEBIH PRODUKSI | B18: =SUMIF('STOK STB BJ'!$P$6:$P$302,A18,'STOK STB BJ'!$L$6:$L$302) -> 48404 | C18: =SUMIF('STOK STB BJ'!$P$6:$P$302,A18,'STOK STB BJ'!$M$6:$M$302) -> 18759.474 | D18: =COUNTIF('STOK STB BJ'!$P$6:$P$302,A18) -> 29
A19: KURANG KIRIM | B19: =SUMIF('STOK STB BJ'!$P$6:$P$302,A19,'STOK STB BJ'!$L$6:$L$302) -> 10090 | C19: =SUMIF('STOK STB BJ'!$P$6:$P$302,A19,'STOK STB BJ'!$M$6:$M$302) -> 5002.1531 | D19: =COUNTIF('STOK STB BJ'!$P$6:$P$302,A19) -> 12
A20: REVISI | B20: =SUMIF('STOK STB BJ'!$P$6:$P$302,A20,'STOK STB BJ'!$L$6:$L$302) -> 0 | C20: =SUMIF('STOK STB BJ'!$P$6:$P$302,A20,'STOK STB BJ'!$M$6:$M$302) -> 0 | D20: =COUNTIF('STOK STB BJ'!$P$6:$P$302,A20) -> 0
A21: TUNGGU JADWAL | B21: =SUMIF('STOK STB BJ'!$P$6:$P$302,A21,'STOK STB BJ'!$L$6:$L$302) -> 87224 | C21: =SUMIF('STOK STB BJ'!$P$6:$P$302,A21,'STOK STB BJ'!$M$6:$M$302) -> 28674.023 | D21: =COUNTIF('STOK STB BJ'!$P$6:$P$302,A21) -> 68
A22: TIDAK SET | B22: =SUMIF('STOK STB BJ'!$P$6:$P$302,A22,'STOK STB BJ'!$L$6:$L$302) -> 4915 | C22: =SUMIF('STOK STB BJ'!$P$6:$P$302,A22,'STOK STB BJ'!$M$6:$M$302) -> 4441.6505 | D22: =COUNTIF('STOK STB BJ'!$P$6:$P$302,A22) -> 9
A23: BELUM KETEMU | B23: =SUMIF('STOK STB BJ'!$P$6:$P$302,A23,'STOK STB BJ'!$L$6:$L$302) -> 465 | C23: =SUMIF('STOK STB BJ'!$P$6:$P$302,A23,'STOK STB BJ'!$M$6:$M$302) -> 319.463 | D23: =COUNTIF('STOK STB BJ'!$P$6:$P$302,A23) -> 3
A24: TANPA KETERANGAN | B24: =SUM('STOK STB BJ'!$L$6:$L$302)-SUM(B15:B23) -> 499496 | C24: =SUM('STOK STB BJ'!$M$6:$M$302)-SUM(C15:C23) -> 152232.18 | D24: =COUNTA('STOK STB BJ'!$B$6:$B$302)-SUM(D15:D23) -> 148
A25: TOTAL | B25: =SUM(B15:B24) -> 776500 | C25: =SUM(C15:C24) -> 238658.73 | D25: =SUM(D15:D24) -> 297

Sheet CATATAN
A1: CATATAN & ASUMSI
A3: Sumber data | B3: BOX_AGUSTUS.xlsx, sheet "BOX" (DAILY STOCK BOX), baris 7 s/d 5122
A4: STOK AWAL | B4: Kolom Q/R "SALDO AWAL" = posisi stok gudang per 01 Agustus 2026
A5: STOK AKHIR | B5: Kolom EM/EN "SALDO AKHIR" = SALDO AWAL + STB harian - DLV harian (terisi s/d 03 Agu 2026)
A6: Validasi 1 | B6: Total STOK AWAL = 758.966 pc / 240.491,44 kg — sama dengan baris total sheet BOX
A7: Validasi 2 | B7: Total STOK AKHIR = 776.500 pc / 238.658,73 kg — sama dengan sheet "Aging Stock" (update 03 Agu 2026)
A8: Filter baris | B8: Hanya baris yang punya CUSTOMER dan stok awal atau stok akhir <> 0 (297 baris)
A9: NO. OP | B9: Diambil dari kolom M (NO. OP aktif); bila kosong dipakai kolom J (NO. OP LAMA). Ini yang dipetakan ke cNoSc di database
A10: Baris ganda | B10: Beberapa NO. OP muncul >1 baris di sheet detail (beda lokasi/batch). Sudah dijumlahkan di sheet REKAP PER OP
A11: Untuk import DB | B11: Pakai sheet REKAP PER OP. Kolom kunci: NO. OP (cNoSc) + STOK AWAL (PC) atau STOK AKHIR (PC)
A12: Mana yang dipakai? | B12: STOK AWAL bila transaksi STB/DLV Agustus tetap dijalankan dari database. STOK AKHIR bila database di-reset per 03 Agu 2026
A13: WAJIB | B13: Backup tabel stok di database sebelum replace — lihat file import_stok_stb_bj.sql
